#include<iostream>
//#include<vcruntime_exception.h>

//int main()
//{
//	try {
//		int res = 11;
//		throw std::runtime_error("division by zero");
//	}
//	catch (std::exception ex)
//	{
//		std::cout << "in catch block" << ex.what() << std::endl;
//	}
//
//}